Internal Server Error: /api/payments/initiate-payment/
Traceback (most recent call last):
  File "C:\Users\onyan\AppData\Roaming\Python\Python313\site-packages\urllib3\connection.py", line 198, in _new_conn
    sock = connection.create_connection(
        (self._dns_host, self.port),
    ...<2 lines>...
        socket_options=self.socket_options,
    )
  File "C:\Users\onyan\AppData\Roaming\Python\Python313\site-packages\urllib3\util\connection.py", line 60, in create_connection
    for res in socket.getaddrinfo(host, port, family, socket.SOCK_STREAM):
               ~~~~~~~~~~~~~~~~~~^^^^^^^^^^^^^^^^^^^^^^^^^^^^^^^^^^^^^^^^
  File "C:\Python313\Lib\socket.py", line 975, in getaddrinfo
    for res in _socket.getaddrinfo(host, port, family, type, proto, flags):
               ~~~~~~~~~~~~~~~~~~~^^^^^^^^^^^^^^^^^^^^^^^^^^^^^^^^^^^^^^^^
socket.gaierror: [Errno 11001] getaddrinfo failed

The above exception was the direct cause of the following exception:

Traceback (most recent call last):
  File "C:\Users\onyan\AppData\Roaming\Python\Python313\site-packages\urllib3\connectionpool.py", line 787, in urlopen
    response = self._make_request(
        conn,
    ...<10 lines>...
        **response_kw,
    )
  File "C:\Users\onyan\AppData\Roaming\Python\Python313\site-packages\urllib3\connectionpool.py", line 488, in _make_request
    raise new_e
  File "C:\Users\onyan\AppData\Roaming\Python\Python313\site-packages\urllib3\connectionpool.py", line 464, in _make_request
    self._validate_conn(conn)
    ~~~~~~~~~~~~~~~~~~~^^^^^^
  File "C:\Users\onyan\AppData\Roaming\Python\Python313\site-packages\urllib3\connectionpool.py", line 1093, in _validate_conn
    conn.connect()
    ~~~~~~~~~~~~^^
  File "C:\Users\onyan\AppData\Roaming\Python\Python313\site-packages\urllib3\connection.py", line 704, in connect
    self.sock = sock = self._new_conn()
                       ~~~~~~~~~~~~~~^^
  File "C:\Users\onyan\AppData\Roaming\Python\Python313\site-packages\urllib3\connection.py", line 205, in _new_conn
    raise NameResolutionError(self.host, self, e) from e
urllib3.exceptions.NameResolutionError: <urllib3.connection.HTTPSConnection object at 0x000001E696EF2900>: Failed to resolve 'pay.pesapal.com' ([Errno 11001] getaddrinfo failed)

The above exception was the direct cause of the following exception:

Traceback (most recent call last):
  File "C:\Users\onyan\AppData\Roaming\Python\Python313\site-packages\requests\adapters.py", line 667, in send
    resp = conn.urlopen(
        method=request.method,
    ...<9 lines>...
        chunked=chunked,
    )
  File "C:\Users\onyan\AppData\Roaming\Python\Python313\site-packages\urllib3\connectionpool.py", line 841, in urlopen
    retries = retries.increment(
        method, url, error=new_e, _pool=self, _stacktrace=sys.exc_info()[2]
    )
  File "C:\Users\onyan\AppData\Roaming\Python\Python313\site-packages\urllib3\util\retry.py", line 519, in increment
    raise MaxRetryError(_pool, url, reason) from reason  # type: ignore[arg-type]
    ^^^^^^^^^^^^^^^^^^^^^^^^^^^^^^^^^^^^^^^^^^^^^^^^^^^
urllib3.exceptions.MaxRetryError: HTTPSConnectionPool(host='pay.pesapal.com', port=443): Max retries exceeded with url: /v3/api/Auth/RequestToken (Caused by NameResolutionError("<urllib3.connection.HTTPSConnection object at 0x000001E696EF2900>: Failed to resolve 'pay.pesapal.com' ([Errno 11001] getaddrinfo failed)"))

During handling of the above exception, another exception occurred:

Traceback (most recent call last):
  File "C:\Users\onyan\AppData\Roaming\Python\Python313\site-packages\django\core\handlers\exception.py", line 55, in inner
    response = get_response(request)
  File "C:\Users\onyan\AppData\Roaming\Python\Python313\site-packages\django\core\handlers\base.py", line 197, in _get_response
    response = wrapped_callback(request, *callback_args, **callback_kwargs)
  File "C:\Users\onyan\AppData\Roaming\Python\Python313\site-packages\django\views\decorators\csrf.py", line 65, in _view_wrapper
    return view_func(request, *args, **kwargs)
  File "C:\Users\onyan\AppData\Roaming\Python\Python313\site-packages\django\views\generic\base.py", line 104, in view
    return self.dispatch(request, *args, **kwargs)
           ~~~~~~~~~~~~~^^^^^^^^^^^^^^^^^^^^^^^^^^
  File "C:\Users\onyan\AppData\Roaming\Python\Python313\site-packages\rest_framework\views.py", line 509, in dispatch
    response = self.handle_exception(exc)
  File "C:\Users\onyan\AppData\Roaming\Python\Python313\site-packages\rest_framework\views.py", line 469, in handle_exception
    self.raise_uncaught_exception(exc)
    ~~~~~~~~~~~~~~~~~~~~~~~~~~~~~^^^^^
  File "C:\Users\onyan\AppData\Roaming\Python\Python313\site-packages\rest_framework\views.py", line 480, in raise_uncaught_exception
    raise exc
  File "C:\Users\onyan\AppData\Roaming\Python\Python313\site-packages\rest_framework\views.py", line 506, in dispatch
    response = handler(request, *args, **kwargs)
  File "D:\projects\python-projects\python-test\server\payment\views.py", line 17, in post
    token = pesapal.get_auth_token()
  File "D:\projects\python-projects\python-test\server\payment\utils.py", line 18, in get_auth_token
    response = requests.post(url, json=payload)
  File "C:\Users\onyan\AppData\Roaming\Python\Python313\site-packages\requests\api.py", line 115, in post
    return request("post", url, data=data, json=json, **kwargs)
  File "C:\Users\onyan\AppData\Roaming\Python\Python313\site-packages\requests\api.py", line 59, in request
    return session.request(method=method, url=url, **kwargs)
           ~~~~~~~~~~~~~~~^^^^^^^^^^^^^^^^^^^^^^^^^^^^^^^^^^
  File "C:\Users\onyan\AppData\Roaming\Python\Python313\site-packages\requests\sessions.py", line 589, in request
    resp = self.send(prep, **send_kwargs)
  File "C:\Users\onyan\AppData\Roaming\Python\Python313\site-packages\requests\sessions.py", line 703, in send
    r = adapter.send(request, **kwargs)
  File "C:\Users\onyan\AppData\Roaming\Python\Python313\site-packages\requests\adapters.py", line 700, in send
    raise ConnectionError(e, request=request)
requests.exceptions.ConnectionError: HTTPSConnectionPool(host='pay.pesapal.com', port=443): Max retries exceeded with url: /v3/api/Auth/RequestToken (Caused by NameResolutionError("<urllib3.connection.HTTPSConnection object at 0x000001E696EF2900>: Failed to resolve 'pay.pesapal.com' ([Errno 11001] getaddrinfo failed)"))
"POST /api/payments/initiate-payment/ HTTP/1.1" 500 145
